<?xml version="1.0" ?>
<robot name="Stewart">

<material name="silver">
  <color rgba="0.700 0.700 0.700 1.000"/>
</material>

<link name="base_link">
  <inertial>
    <origin xyz="2.3255899752716172e-11 -1.1937183962455178e-11 0.013288962255547656" rpy="0 0 0"/>
    <mass value="13.757667475145922"/>
    <inertia ixx="0.21797416015774124" iyy="0.2179741700510937" izz="0.4340771179526647" ixy="3.067776560401459e-11" iyz="4.670150176529436e-12" ixz="-8.804667573970036e-12"/>
  </inertial>
  <visual>
    <origin xyz="0 0 0" rpy="0 0 0"/>
    <geometry>
      <mesh filename="meshes/base_link.stl" scale="0.001 0.001 0.001"/>
    </geometry>
    <material name="silver"/>
    <material/>
  </visual>
  <collision>
    <origin xyz="0 0 0" rpy="0 0 0"/>
    <geometry>
      <mesh filename="meshes/base_link.stl" scale="0.001 0.001 0.001"/>
    </geometry>
  </collision>
</link>

<link name="X1bottom1">
  <inertial>
    <origin xyz="0.012750034781542574 0.022083926967425505 -4.07240130076425e-07" rpy="0 0 0"/>
    <mass value="0.015369342112821462"/>
    <inertia ixx="2.084365263984602e-06" iyy="1.9211221879191767e-06" izz="3.3040955648304437e-06" ixy="-1.4137265086372345e-07" iyz="-3.4574917186284927e-07" ixz="5.988551323401657e-07"/>
  </inertial>
  <visual>
    <origin xyz="0.160375 0.15639 -0.064756" rpy="0 0 0"/>
    <geometry>
      <mesh filename="meshes/X1bottom1.stl" scale="0.001 0.001 0.001"/>
    </geometry>
    <material name="silver"/>
    <material/>
  </visual>
  <collision>
    <origin xyz="0.160375 0.15639 -0.064756" rpy="0 0 0"/>
    <geometry>
      <mesh filename="meshes/X1bottom1.stl" scale="0.001 0.001 0.001"/>
    </geometry>
  </collision>
</link>

<link name="X6bottom1">
  <inertial>
    <origin xyz="-0.025500046262033477 -6.64043929288205e-08 -4.0724012435877643e-07" rpy="0 0 0"/>
    <mass value="0.015369342112821437"/>
    <inertia ixx="1.8395006492809914e-06" iyy="1.9359846193172324e-06" izz="3.534097746554256e-06" ixy="-1.5720931501039814e-18" iyz="-4.0435313273422735e-07" ixz="6.505213034913027e-19"/>
  </inertial>
  <visual>
    <origin xyz="-0.173125 0.134306 -0.064756" rpy="0 0 0"/>
    <geometry>
      <mesh filename="meshes/X6bottom1.stl" scale="0.001 0.001 0.001"/>
    </geometry>
    <material name="silver"/>
    <material/>
  </visual>
  <collision>
    <origin xyz="-0.173125 0.134306 -0.064756" rpy="0 0 0"/>
    <geometry>
      <mesh filename="meshes/X6bottom1.stl" scale="0.001 0.001 0.001"/>
    </geometry>
  </collision>
</link>

<link name="X5bottom1">
  <inertial>
    <origin xyz="-0.02550004626203478 6.64043108555834e-08 -4.072401355581512e-07" rpy="0 0 0"/>
    <mass value="0.015369342112821526"/>
    <inertia ixx="1.8395006498894727e-06" iyy="2.172764835612533e-06" izz="3.2973175311558616e-06" ixy="6.505213034913027e-19" iyz="6.970209157905062e-07" ixz="-6.776263578034403e-19"/>
  </inertial>
  <visual>
    <origin xyz="-0.215625 0.060694 -0.064756" rpy="0 0 0"/>
    <geometry>
      <mesh filename="meshes/X5bottom1.stl" scale="0.001 0.001 0.001"/>
    </geometry>
    <material name="silver"/>
    <material/>
  </visual>
  <collision>
    <origin xyz="-0.215625 0.060694 -0.064756" rpy="0 0 0"/>
    <geometry>
      <mesh filename="meshes/X5bottom1.stl" scale="0.001 0.001 0.001"/>
    </geometry>
  </collision>
</link>

<link name="X2bottom1">
  <inertial>
    <origin xyz="0.012750057742457938 0.02208407303261209 -4.0724011943216176e-07" rpy="0 0 0"/>
    <mass value="0.01536934211282146"/>
    <inertia ixx="1.9154889064606698e-06" iyy="1.8648300683498514e-06" izz="3.52926404049189e-06" ixy="-4.387184072903198e-08" iyz="2.0688336118809613e-07" ixz="-3.583324928187583e-07"/>
  </inertial>
  <visual>
    <origin xyz="0.202875 0.082778 -0.064756" rpy="0 0 0"/>
    <geometry>
      <mesh filename="meshes/X2bottom1.stl" scale="0.001 0.001 0.001"/>
    </geometry>
    <material name="silver"/>
    <material/>
  </visual>
  <collision>
    <origin xyz="0.202875 0.082778 -0.064756" rpy="0 0 0"/>
    <geometry>
      <mesh filename="meshes/X2bottom1.stl" scale="0.001 0.001 0.001"/>
    </geometry>
  </collision>
</link>

<link name="X4bottom1">
  <inertial>
    <origin xyz="-0.01275001148042354 0.02208399337177483 -4.0724011900195034e-07" rpy="0 0 0"/>
    <mass value="0.015369342112821484"/>
    <inertia ixx="1.9105114098006163e-06" iyy="1.8631709027955968e-06" izz="3.5359007027058187e-06" ixy="4.0998081692929103e-08" iyz="2.0038517759793806e-07" ixz="3.470773086839383e-07"/>
  </inertial>
  <visual>
    <origin xyz="-0.05525 -0.172916 -0.064756" rpy="0 0 0"/>
    <geometry>
      <mesh filename="meshes/X4bottom1.stl" scale="0.001 0.001 0.001"/>
    </geometry>
    <material name="silver"/>
    <material/>
  </visual>
  <collision>
    <origin xyz="-0.05525 -0.172916 -0.064756" rpy="0 0 0"/>
    <geometry>
      <mesh filename="meshes/X4bottom1.stl" scale="0.001 0.001 0.001"/>
    </geometry>
  </collision>
</link>

<link name="X3bottom1">
  <inertial>
    <origin xyz="-0.012749988519508704 0.022084006628265207 -4.0724013015969174e-07" rpy="0 0 0"/>
    <mass value="0.015369342112821385"/>
    <inertia ixx="2.0920363194620656e-06" iyy="1.9236792064083623e-06" izz="3.293867490850879e-06" ixy="1.4580153681278572e-07" iyz="-3.4989498656401896e-07" ixz="-6.06035894043035e-07"/>
  </inertial>
  <visual>
    <origin xyz="0.02975 -0.172916 -0.064756" rpy="0 0 0"/>
    <geometry>
      <mesh filename="meshes/X3bottom1.stl" scale="0.001 0.001 0.001"/>
    </geometry>
    <material name="silver"/>
    <material/>
  </visual>
  <collision>
    <origin xyz="0.02975 -0.172916 -0.064756" rpy="0 0 0"/>
    <geometry>
      <mesh filename="meshes/X3bottom1.stl" scale="0.001 0.001 0.001"/>
    </geometry>
  </collision>
</link>

<link name="cylinder61">
  <inertial>
    <origin xyz="-0.04918434904597231 -0.05287862749126965 0.11066211878578129" rpy="0 0 0"/>
    <mass value="1.0834595415274024"/>
    <inertia ixx="0.003931029690579582" iyy="0.004331438955675698" izz="0.0011906258425340571" ixy="-0.0003353486833466146" iyz="0.0007946758036431328" ixz="0.0014054232697529832"/>
  </inertial>
  <visual>
    <origin xyz="-0.147625 0.109259 -0.070732" rpy="0 0 0"/>
    <geometry>
      <mesh filename="meshes/cylinder61.stl" scale="0.001 0.001 0.001"/>
    </geometry>
    <material name="silver"/>
    <material/>
  </visual>
  <collision>
    <origin xyz="-0.147625 0.109259 -0.070732" rpy="0 0 0"/>
    <geometry>
      <mesh filename="meshes/cylinder61.stl" scale="0.001 0.001 0.001"/>
    </geometry>
  </collision>
</link>

<link name="cylinder51">
  <inertial>
    <origin xyz="-0.0004859817530507571 0.07913805533522147 0.10582169844859306" rpy="0 0 0"/>
    <mass value="1.0834593359661664"/>
    <inertia ixx="0.0045236090842445675" iyy="0.00375582949509122" izz="0.001173648926438016" ixy="6.655292627263292e-06" iyz="-0.0016004734534385834" ixz="1.3919592264648173e-05"/>
  </inertial>
  <visual>
    <origin xyz="-0.190125 0.083925 -0.075863" rpy="0 0 0"/>
    <geometry>
      <mesh filename="meshes/cylinder51.stl" scale="0.001 0.001 0.001"/>
    </geometry>
    <material name="silver"/>
    <material/>
  </visual>
  <collision>
    <origin xyz="-0.190125 0.083925 -0.075863" rpy="0 0 0"/>
    <geometry>
      <mesh filename="meshes/cylinder51.stl" scale="0.001 0.001 0.001"/>
    </geometry>
  </collision>
</link>

<link name="cylinder11">
  <inertial>
    <origin xyz="0.027679031631056533 -0.01615886449286605 0.12819492556868725" rpy="0 0 0"/>
    <mass value="1.0834595971642158"/>
    <inertia ixx="0.003961270893089702" iyy="0.004333780915973265" izz="0.0011580440629181954" ixy="0.00032679379954486665" iyz="0.0007977502915447882" ixz="-0.0013728685448845604"/>
  </inertial>
  <visual>
    <origin xyz="0.127459 0.145949 -0.053762" rpy="0 0 0"/>
    <geometry>
      <mesh filename="meshes/cylinder11.stl" scale="0.001 0.001 0.001"/>
    </geometry>
    <material name="silver"/>
    <material/>
  </visual>
  <collision>
    <origin xyz="0.127459 0.145949 -0.053762" rpy="0 0 0"/>
    <geometry>
      <mesh filename="meshes/cylinder11.stl" scale="0.001 0.001 0.001"/>
    </geometry>
  </collision>
</link>

<link name="cylinder21">
  <inertial>
    <origin xyz="-0.02214597551926259 0.06882930176160315 0.1106042549760402" rpy="0 0 0"/>
    <mass value="1.0834595997030583"/>
    <inertia ixx="0.004521764122383441" iyy="0.0037458663101917478" izz="0.0011854653467073123" ixy="7.769778620969376e-06" iyz="-0.0016103811645094381" ixz="1.3367128346729318e-05"/>
  </inertial>
  <visual>
    <origin xyz="0.168465 0.073199 -0.07088" rpy="0 0 0"/>
    <geometry>
      <mesh filename="meshes/cylinder21.stl" scale="0.001 0.001 0.001"/>
    </geometry>
    <material name="silver"/>
    <material/>
  </visual>
  <collision>
    <origin xyz="0.168465 0.073199 -0.07088" rpy="0 0 0"/>
    <geometry>
      <mesh filename="meshes/cylinder21.stl" scale="0.001 0.001 0.001"/>
    </geometry>
  </collision>
</link>

<link name="cylinder31">
  <inertial>
    <origin xyz="-0.06900668487132594 -0.03927565360067878 0.10562619849582729" rpy="0 0 0"/>
    <mass value="1.0834597856232793"/>
    <inertia ixx="0.003935998987140948" iyy="0.0043355285821549475" izz="0.0011815729850209941" ixy="-0.00033251703539186744" iyz="0.0007912799527111589" ixz="0.001398565608451037"/>
  </inertial>
  <visual>
    <origin xyz="0.022405 -0.206602 -0.07592" rpy="0 0 0"/>
    <geometry>
      <mesh filename="meshes/cylinder31.stl" scale="0.001 0.001 0.001"/>
    </geometry>
    <material name="silver"/>
    <material/>
  </visual>
  <collision>
    <origin xyz="0.022405 -0.206602 -0.07592" rpy="0 0 0"/>
    <geometry>
      <mesh filename="meshes/cylinder31.stl" scale="0.001 0.001 0.001"/>
    </geometry>
  </collision>
</link>

<link name="cylinder41">
  <inertial>
    <origin xyz="0.026360716070562548 -0.04045811761718601 0.12300236186687408" rpy="0 0 0"/>
    <mass value="1.083459390274659"/>
    <inertia ixx="0.003955875101816386" iyy="0.004331963660871262" izz="0.001165249847257084" ixy="0.00032777770212437385" iyz="0.0008013649666691741" ixz="-0.0013781057966789113"/>
  </inertial>
  <visual>
    <origin xyz="-0.064203 -0.20753 -0.058835" rpy="0 0 0"/>
    <geometry>
      <mesh filename="meshes/cylinder41.stl" scale="0.001 0.001 0.001"/>
    </geometry>
    <material name="silver"/>
    <material/>
  </visual>
  <collision>
    <origin xyz="-0.064203 -0.20753 -0.058835" rpy="0 0 0"/>
    <geometry>
      <mesh filename="meshes/cylinder41.stl" scale="0.001 0.001 0.001"/>
    </geometry>
  </collision>
</link>

<link name="rod11">
  <inertial>
    <origin xyz="-0.03669234752605403 0.021321590239931215 -0.08988297425474576" rpy="0 0 0"/>
    <mass value="0.2833716573537993"/>
    <inertia ixx="0.000823902654109393" iyy="0.0009085197934918156" izz="0.00018505910049279248" ixy="7.423528261029082e-05" iyz="0.00018184738918601215" ixz="-0.0003129468812543765"/>
  </inertial>
  <visual>
    <origin xyz="0.059027 0.185789 -0.281787" rpy="0 0 0"/>
    <geometry>
      <mesh filename="meshes/rod11.stl" scale="0.001 0.001 0.001"/>
    </geometry>
    <material name="silver"/>
    <material/>
  </visual>
  <collision>
    <origin xyz="0.059027 0.185789 -0.281787" rpy="0 0 0"/>
    <geometry>
      <mesh filename="meshes/rod11.stl" scale="0.001 0.001 0.001"/>
    </geometry>
  </collision>
</link>

<link name="rod21">
  <inertial>
    <origin xyz="0.00037095794647595826 -0.04297719725828332 -0.0890675531341732" rpy="0 0 0"/>
    <mass value="0.2833716573537998"/>
    <inertia ixx="0.0009516433027025335" iyy="0.000774608025275101" izz="0.00019123022011655576" ixy="1.5275741736574117e-06" iyz="-0.0003669227394076931" ixz="3.1658095691923516e-06"/>
  </inertial>
  <visual>
    <origin xyz="0.191025 -0.043606 -0.280911" rpy="0 0 0"/>
    <geometry>
      <mesh filename="meshes/rod21.stl" scale="0.001 0.001 0.001"/>
    </geometry>
    <material name="silver"/>
    <material/>
  </visual>
  <collision>
    <origin xyz="0.191025 -0.043606 -0.280911" rpy="0 0 0"/>
    <geometry>
      <mesh filename="meshes/rod21.stl" scale="0.001 0.001 0.001"/>
    </geometry>
  </collision>
</link>

<link name="rod31">
  <inertial>
    <origin xyz="0.037368961812755036 0.02114222879717423 -0.08922801503409522" rpy="0 0 0"/>
    <mass value="0.2833716573537997"/>
    <inertia ixx="0.0008181425222781279" iyy="0.0009089165651000094" izz="0.0001904224607157841" ixy="-7.55405563361124e-05" iyz="0.0001803748300181745" ixz="0.0003188030254016438"/>
  </inertial>
  <visual>
    <origin xyz="0.133074 -0.143755 -0.281026" rpy="0 0 0"/>
    <geometry>
      <mesh filename="meshes/rod31.stl" scale="0.001 0.001 0.001"/>
    </geometry>
    <material name="silver"/>
    <material/>
  </visual>
  <collision>
    <origin xyz="0.133074 -0.143755 -0.281026" rpy="0 0 0"/>
    <geometry>
      <mesh filename="meshes/rod31.stl" scale="0.001 0.001 0.001"/>
    </geometry>
  </collision>
</link>

<link name="rod41">
  <inertial>
    <origin xyz="-0.03671432893419034 0.021333835501112397 -0.08943560564723566" rpy="0 0 0"/>
    <mass value="0.28337165735379954"/>
    <inertia ixx="0.0008227318902040391" iyy="0.0009081267075151493" izz="0.00018662295037495148" ixy="7.491367373303661e-05" iyz="0.00018248763684370478" ixz="-0.0003140567406109589"/>
  </inertial>
  <visual>
    <origin xyz="-0.131503 -0.143283 -0.281565" rpy="0 0 0"/>
    <geometry>
      <mesh filename="meshes/rod41.stl" scale="0.001 0.001 0.001"/>
    </geometry>
    <material name="silver"/>
    <material/>
  </visual>
  <collision>
    <origin xyz="-0.131503 -0.143283 -0.281565" rpy="0 0 0"/>
    <geometry>
      <mesh filename="meshes/rod41.stl" scale="0.001 0.001 0.001"/>
    </geometry>
  </collision>
</link>

<link name="rod51">
  <inertial>
    <origin xyz="0.0003692450240128653 -0.04246867944257937 -0.08882427581090685" rpy="0 0 0"/>
    <mass value="0.28337165735379943"/>
    <inertia ixx="0.0009516433050549174" iyy="0.0007772217479401627" izz="0.0001886164950989349" ixy="1.5161213266943614e-06" iyz="-0.0003648296558216372" ixz="3.170962611553224e-06"/>
  </inertial>
  <visual>
    <origin xyz="-0.189225 -0.042833 -0.281283" rpy="0 0 0"/>
    <geometry>
      <mesh filename="meshes/rod51.stl" scale="0.001 0.001 0.001"/>
    </geometry>
    <material name="silver"/>
    <material/>
  </visual>
  <collision>
    <origin xyz="-0.189225 -0.042833 -0.281283" rpy="0 0 0"/>
    <geometry>
      <mesh filename="meshes/rod51.stl" scale="0.001 0.001 0.001"/>
    </geometry>
  </collision>
</link>

<link name="rod61">
  <inertial>
    <origin xyz="0.037549719675037105 0.02124781812642279 -0.08904704529964502" rpy="0 0 0"/>
    <mass value="0.2833716573537993"/>
    <inertia ixx="0.0008166498088893609" iyy="0.0009084275209417948" izz="0.00019240421826258354" ixy="-7.639501504529741e-05" iyz="0.00018116756617676984" ixz="0.00032016265042498875"/>
  </inertial>
  <visual>
    <origin xyz="-0.056546 0.185844 -0.280745" rpy="0 0 0"/>
    <geometry>
      <mesh filename="meshes/rod61.stl" scale="0.001 0.001 0.001"/>
    </geometry>
    <material name="silver"/>
    <material/>
  </visual>
  <collision>
    <origin xyz="-0.056546 0.185844 -0.280745" rpy="0 0 0"/>
    <geometry>
      <mesh filename="meshes/rod61.stl" scale="0.001 0.001 0.001"/>
    </geometry>
  </collision>
</link>

<link name="piston11">
  <inertial>
    <origin xyz="0.0032860331417977687 -0.001908766209624907 0.008047604270945363" rpy="0 0 0"/>
    <mass value="0.0857844309920109"/>
    <inertia ixx="1.9053601269514858e-05" iyy="1.9509048384626186e-05" izz="2.6770943186938886e-05" ixy="-1.765300356624264e-06" iyz="-1.4155248973532833e-06" ixz="3.440522019570102e-06"/>
  </inertial>
  <visual>
    <origin xyz="0.058804 0.185918 -0.282332" rpy="0 0 0"/>
    <geometry>
      <mesh filename="meshes/piston11.stl" scale="0.001 0.001 0.001"/>
    </geometry>
    <material name="silver"/>
    <material/>
  </visual>
  <collision>
    <origin xyz="0.058804 0.185918 -0.282332" rpy="0 0 0"/>
    <geometry>
      <mesh filename="meshes/piston11.stl" scale="0.001 0.001 0.001"/>
    </geometry>
  </collision>
</link>

<link name="piston21">
  <inertial>
    <origin xyz="-3.3367295559777466e-05 0.0038670723842009896 0.008016432339832846" rpy="0 0 0"/>
    <mass value="0.08578414622058636"/>
    <inertia ixx="1.9717869511112242e-05" iyy="1.925995738403033e-05" izz="2.6355219481958257e-05" ixy="-2.0560454930393032e-08" iyz="4.465263225179872e-06" ixz="-2.667664152772309e-08"/>
  </inertial>
  <visual>
    <origin xyz="0.191029 -0.044086 -0.281906" rpy="0 0 0"/>
    <geometry>
      <mesh filename="meshes/piston21.stl" scale="0.001 0.001 0.001"/>
    </geometry>
    <material name="silver"/>
    <material/>
  </visual>
  <collision>
    <origin xyz="0.191029 -0.044086 -0.281906" rpy="0 0 0"/>
    <geometry>
      <mesh filename="meshes/piston21.stl" scale="0.001 0.001 0.001"/>
    </geometry>
  </collision>
</link>

<link name="piston31">
  <inertial>
    <origin xyz="-0.0033589282518494135 -0.0019007846162378828 0.008019414134661285" rpy="0 0 0"/>
    <mass value="0.08578406699699544"/>
    <inertia ixx="2.0970010552245205e-05" iyy="1.76442756564376e-05" izz="2.671871353242131e-05" ixy="7.045497514069667e-07" iyz="-2.277973286179697e-06" ixz="-2.9910830972889636e-06"/>
  </inertial>
  <visual>
    <origin xyz="0.133443 -0.143545 -0.281909" rpy="0 0 0"/>
    <geometry>
      <mesh filename="meshes/piston31.stl" scale="0.001 0.001 0.001"/>
    </geometry>
    <material name="silver"/>
    <material/>
  </visual>
  <collision>
    <origin xyz="0.133443 -0.143545 -0.281909" rpy="0 0 0"/>
    <geometry>
      <mesh filename="meshes/piston31.stl" scale="0.001 0.001 0.001"/>
    </geometry>
  </collision>
</link>

<link name="piston61">
  <inertial>
    <origin xyz="-0.003376585564749575 -0.0019105484034558917 0.008010209828523351" rpy="0 0 0"/>
    <mass value="0.08578421036573612"/>
    <inertia ixx="1.939597655353613e-05" iyy="1.959627509969409e-05" izz="2.6341041616389192e-05" ixy="-1.984208581616619e-07" iyz="-2.211568689989424e-06" ixz="-3.892195425233202e-06"/>
  </inertial>
  <visual>
    <origin xyz="-0.056147 0.18607 -0.281691" rpy="0 0 0"/>
    <geometry>
      <mesh filename="meshes/piston61.stl" scale="0.001 0.001 0.001"/>
    </geometry>
    <material name="silver"/>
    <material/>
  </visual>
  <collision>
    <origin xyz="-0.056147 0.18607 -0.281691" rpy="0 0 0"/>
    <geometry>
      <mesh filename="meshes/piston61.stl" scale="0.001 0.001 0.001"/>
    </geometry>
  </collision>
</link>

<link name="piston51">
  <inertial>
    <origin xyz="-3.378133003123507e-05 0.0038392545337441464 0.008029531348262398" rpy="0 0 0"/>
    <mass value="0.0857842395803521"/>
    <inertia ixx="1.787190707838119e-05" iyy="2.0732384428599065e-05" izz="2.672901543623483e-05" ixy="1.0569755338982753e-06" iyz="3.7226061677824752e-06" ixz="-5.48178695439043e-07"/>
  </inertial>
  <visual>
    <origin xyz="-0.189219 -0.0435 -0.282676" rpy="0 0 0"/>
    <geometry>
      <mesh filename="meshes/piston51.stl" scale="0.001 0.001 0.001"/>
    </geometry>
    <material name="silver"/>
    <material/>
  </visual>
  <collision>
    <origin xyz="-0.189219 -0.0435 -0.282676" rpy="0 0 0"/>
    <geometry>
      <mesh filename="meshes/piston51.stl" scale="0.001 0.001 0.001"/>
    </geometry>
  </collision>
</link>

<link name="piston41">
  <inertial>
    <origin xyz="0.0032993913873551606 -0.0019177316503581898 0.008040026546995316" rpy="0 0 0"/>
    <mass value="0.08578412180440002"/>
    <inertia ixx="1.933172949617791e-05" iyy="1.959002115996776e-05" izz="2.641133849987532e-05" ixy="2.2217075743512747e-07" iyz="-2.2199072712142387e-06" ixz="3.822362329130788e-06"/>
  </inertial>
  <visual>
    <origin xyz="-0.131873 -0.143069 -0.282465" rpy="0 0 0"/>
    <geometry>
      <mesh filename="meshes/piston41.stl" scale="0.001 0.001 0.001"/>
    </geometry>
    <material name="silver"/>
    <material/>
  </visual>
  <collision>
    <origin xyz="-0.131873 -0.143069 -0.282465" rpy="0 0 0"/>
    <geometry>
      <mesh filename="meshes/piston41.stl" scale="0.001 0.001 0.001"/>
    </geometry>
  </collision>
</link>

<link name="X6top1">
  <inertial>
    <origin xyz="-0.019884329978111126 -0.011455391103538243 -0.01111838207559357" rpy="0 0 0"/>
    <mass value="0.015369342112822157"/>
    <inertia ixx="2.0966112409073236e-06" iyy="1.9229015181614593e-06" izz="3.2900702580339596e-06" ixy="1.4643512722555983e-07" iyz="-3.478200178871861e-07" ixz="-6.107018993516925e-07"/>
  </inertial>
  <visual>
    <origin xyz="-0.06085 0.183205 -0.328812" rpy="0 0 0"/>
    <geometry>
      <mesh filename="meshes/X6top1.stl" scale="0.001 0.001 0.001"/>
    </geometry>
    <material name="silver"/>
    <material/>
  </visual>
  <collision>
    <origin xyz="-0.06085 0.183205 -0.328812" rpy="0 0 0"/>
    <geometry>
      <mesh filename="meshes/X6top1.stl" scale="0.001 0.001 0.001"/>
    </geometry>
  </collision>
</link>

<link name="X1top1">
  <inertial>
    <origin xyz="-0.02152313892009481 -0.01235951595005999 0.005854677154071231" rpy="0 0 0"/>
    <mass value="0.015369342112821587"/>
    <inertia ixx="1.909792831357015e-06" iyy="1.8636226355129779e-06" izz="3.5361675484964e-06" ixy="4.117750653656409e-08" iyz="2.023041660983776e-07" ixz="3.4534391380207016e-07"/>
  </inertial>
  <visual>
    <origin xyz="0.022513 0.18214 -0.312653" rpy="0 0 0"/>
    <geometry>
      <mesh filename="meshes/X1top1.stl" scale="0.001 0.001 0.001"/>
    </geometry>
    <material name="silver"/>
    <material/>
  </visual>
  <collision>
    <origin xyz="0.022513 0.18214 -0.312653" rpy="0 0 0"/>
    <geometry>
      <mesh filename="meshes/X1top1.stl" scale="0.001 0.001 0.001"/>
    </geometry>
  </collision>
</link>

<link name="X4top1">
  <inertial>
    <origin xyz="-0.019928843799850188 0.011553182075629997 0.010936840063824949" rpy="0 0 0"/>
    <mass value="0.015369342112821678"/>
    <inertia ixx="2.0859176366161934e-06" iyy="1.9225594856740573e-06" izz="3.301105894605084e-06" ixy="-1.4306330072965008e-07" iyz="-3.4842392312940586e-07" ixz="6.001369517963807e-07"/>
  </inertial>
  <visual>
    <origin xyz="-0.166637 -0.122895 -0.307667" rpy="0 0 0"/>
    <geometry>
      <mesh filename="meshes/X4top1.stl" scale="0.001 0.001 0.001"/>
    </geometry>
    <material name="silver"/>
    <material/>
  </visual>
  <collision>
    <origin xyz="-0.166637 -0.122895 -0.307667" rpy="0 0 0"/>
    <geometry>
      <mesh filename="meshes/X4top1.stl" scale="0.001 0.001 0.001"/>
    </geometry>
  </collision>
</link>

<link name="X5top1">
  <inertial>
    <origin xyz="-0.021432666326504285 0.012430257832952249 -0.006031718040156786" rpy="0 0 0"/>
    <mass value="0.015369342112821503"/>
    <inertia ixx="1.9145953500986426e-06" iyy="1.8646298286417902e-06" izz="3.5303578365613415e-06" ixy="-4.3440398303544936e-08" iyz="2.0613067116669482e-07" ixz="-3.5633469499759575e-07"/>
  </inertial>
  <visual>
    <origin xyz="-0.210502 -0.048326 -0.3248" rpy="0 0 0"/>
    <geometry>
      <mesh filename="meshes/X5top1.stl" scale="0.001 0.001 0.001"/>
    </geometry>
    <material name="silver"/>
    <material/>
  </visual>
  <collision>
    <origin xyz="-0.210502 -0.048326 -0.3248" rpy="0 0 0"/>
    <geometry>
      <mesh filename="meshes/X5top1.stl" scale="0.001 0.001 0.001"/>
    </geometry>
  </collision>
</link>

<link name="UJ11">
  <inertial>
    <origin xyz="-0.012901320067681007 0.02235541921296119 0.030918951565010233" rpy="0 0 0"/>
    <mass value="0.08446437141832058"/>
    <inertia ixx="1.876023436132336e-05" iyy="1.744504109833442e-05" izz="2.8099988017196882e-05" ixy="1.1291371680207524e-06" iyz="1.4108623411050736e-08" ixz="-2.2336470638156455e-08"/>
  </inertial>
  <visual>
    <origin xyz="0.031203 0.216824 -0.318557" rpy="0 0 0"/>
    <geometry>
      <mesh filename="meshes/UJ11.stl" scale="0.001 0.001 0.001"/>
    </geometry>
    <material name="silver"/>
    <material/>
  </visual>
  <collision>
    <origin xyz="0.031203 0.216824 -0.318557" rpy="0 0 0"/>
    <geometry>
      <mesh filename="meshes/UJ11.stl" scale="0.001 0.001 0.001"/>
    </geometry>
  </collision>
</link>

<link name="UJ61">
  <inertial>
    <origin xyz="-0.012901749667754182 0.022354644331419343 0.031467384378020324" rpy="0 0 0"/>
    <mass value="0.08976580902108108"/>
    <inertia ixx="2.0019277905727537e-05" iyy="1.8704085452457206e-05" izz="2.9756697223576756e-05" ixy="1.1291434924289804e-06" iyz="1.1958949313467526e-08" ixz="-2.153997661919621e-08"/>
  </inertial>
  <visual>
    <origin xyz="-0.053799 0.216985 -0.317743" rpy="0 0 0"/>
    <geometry>
      <mesh filename="meshes/UJ61.stl" scale="0.001 0.001 0.001"/>
    </geometry>
    <material name="silver"/>
    <material/>
  </visual>
  <collision>
    <origin xyz="-0.053799 0.216985 -0.317743" rpy="0 0 0"/>
    <geometry>
      <mesh filename="meshes/UJ61.stl" scale="0.001 0.001 0.001"/>
    </geometry>
  </collision>
</link>

<link name="UJ51">
  <inertial>
    <origin xyz="-0.012984746110454831 -0.022246344094046792 0.030961558117041488" rpy="0 0 0"/>
    <mass value="0.08446437135496648"/>
    <inertia ixx="1.8751746395966745e-05" iyy="1.7453513557717792e-05" izz="2.8100003288463772e-05" ixy="-1.1340783496491084e-06" iyz="6.565027374592219e-09" ixz="-1.9999536202477963e-08"/>
  </inertial>
  <visual>
    <origin xyz="-0.201986 -0.083032 -0.318775" rpy="0 0 0"/>
    <geometry>
      <mesh filename="meshes/UJ51.stl" scale="0.001 0.001 0.001"/>
    </geometry>
    <material name="silver"/>
    <material/>
  </visual>
  <collision>
    <origin xyz="-0.201986 -0.083032 -0.318775" rpy="0 0 0"/>
    <geometry>
      <mesh filename="meshes/UJ51.stl" scale="0.001 0.001 0.001"/>
    </geometry>
  </collision>
</link>

<link name="UJ41">
  <inertial>
    <origin xyz="-0.01298413751315311 -0.022244824259378043 0.030962116383411564" rpy="0 0 0"/>
    <mass value="0.08446437135502768"/>
    <inertia ixx="1.8751740512846365e-05" iyy="1.7453518773330456e-05" izz="2.810000395610116e-05" ixy="-1.1340828828861754e-06" iyz="9.23948277001957e-09" ixz="-1.865370766358787e-08"/>
  </inertial>
  <visual>
    <origin xyz="-0.159625 -0.156724 -0.31861" rpy="0 0 0"/>
    <geometry>
      <mesh filename="meshes/UJ41.stl" scale="0.001 0.001 0.001"/>
    </geometry>
    <material name="silver"/>
    <material/>
  </visual>
  <collision>
    <origin xyz="-0.159625 -0.156724 -0.31861" rpy="0 0 0"/>
    <geometry>
      <mesh filename="meshes/UJ41.stl" scale="0.001 0.001 0.001"/>
    </geometry>
  </collision>
</link>

<link name="X3top1">
  <inertial>
    <origin xyz="-3.353402112657444e-05 -0.02480945290756348 -0.0058930206690691045" rpy="0 0 0"/>
    <mass value="0.01536934211282155"/>
    <inertia ixx="1.8395124146508655e-06" iyy="1.9351469152733506e-06" izz="3.534923685234335e-06" ixy="1.0608081139852274e-09" iyz="-4.026920449144711e-07" ixz="-4.4662379918535e-09"/>
  </inertial>
  <visual>
    <origin xyz="0.148507 -0.159813 -0.323851" rpy="0 0 0"/>
    <geometry>
      <mesh filename="meshes/X3top1.stl" scale="0.001 0.001 0.001"/>
    </geometry>
    <material name="silver"/>
    <material/>
  </visual>
  <collision>
    <origin xyz="0.148507 -0.159813 -0.323851" rpy="0 0 0"/>
    <geometry>
      <mesh filename="meshes/X3top1.stl" scale="0.001 0.001 0.001"/>
    </geometry>
  </collision>
</link>

<link name="UJ31">
  <inertial>
    <origin xyz="-0.02581633328792031 7.880147311892238e-05 0.030912257401207344" rpy="0 0 0"/>
    <mass value="0.08446437149876589"/>
    <inertia ixx="1.679597726476391e-05" iyy="1.9409288641615563e-05" izz="2.8099997708991124e-05" ixy="4.877295347325075e-09" iyz="8.570491240311728e-09" ixz="-2.3217168030990887e-08"/>
  </inertial>
  <visual>
    <origin xyz="0.122791 -0.134955 -0.318014" rpy="0 0 0"/>
    <geometry>
      <mesh filename="meshes/UJ31.stl" scale="0.001 0.001 0.001"/>
    </geometry>
    <material name="silver"/>
    <material/>
  </visual>
  <collision>
    <origin xyz="0.122791 -0.134955 -0.318014" rpy="0 0 0"/>
    <geometry>
      <mesh filename="meshes/UJ31.stl" scale="0.001 0.001 0.001"/>
    </geometry>
  </collision>
</link>

<link name="X2top1">
  <inertial>
    <origin xyz="-6.697981582351464e-05 -0.02296647705208031 0.01108148332027259" rpy="0 0 0"/>
    <mass value="0.015369342112821333"/>
    <inertia ixx="1.8395030297678038e-06" iyy="2.1777483743459086e-06" izz="3.2923316124506153e-06" ixy="-8.972180309634297e-10" iyz="7.010112469824363e-07" ixz="-1.8594653816922727e-09"/>
  </inertial>
  <visual>
    <origin xyz="0.191112 -0.084438 -0.306855" rpy="0 0 0"/>
    <geometry>
      <mesh filename="meshes/X2top1.stl" scale="0.001 0.001 0.001"/>
    </geometry>
    <material name="silver"/>
    <material/>
  </visual>
  <collision>
    <origin xyz="0.191112 -0.084438 -0.306855" rpy="0 0 0"/>
    <geometry>
      <mesh filename="meshes/X2top1.stl" scale="0.001 0.001 0.001"/>
    </geometry>
  </collision>
</link>

<link name="UJ21">
  <inertial>
    <origin xyz="0.025681445954029408 -1.8339695058454397e-05 0.031024757625217725" rpy="0 0 0"/>
    <mass value="0.0844643714988272"/>
    <inertia ixx="1.6795990332425445e-05" iyy="1.9409288307042916e-05" izz="2.8099984976238772e-05" ixy="4.874755765498992e-09" iyz="8.398825725825995e-09" ixz="-2.6206504313841528e-08"/>
  </inertial>
  <visual>
    <origin xyz="0.216929 -0.06152 -0.31788" rpy="0 0 0"/>
    <geometry>
      <mesh filename="meshes/UJ21.stl" scale="0.001 0.001 0.001"/>
    </geometry>
    <material name="silver"/>
    <material/>
  </visual>
  <collision>
    <origin xyz="0.216929 -0.06152 -0.31788" rpy="0 0 0"/>
    <geometry>
      <mesh filename="meshes/UJ21.stl" scale="0.001 0.001 0.001"/>
    </geometry>
  </collision>
</link>

<link name="J1B_1">
  <inertial>
    <origin xyz="-1.136013436084382e-06 7.288732258858843e-07 0.0005001546051589534" rpy="0 0 0"/>
    <mass value="0.015413438956675112"/>
    <inertia ixx="2.4096457891830715e-06" iyy="2.4096365787221186e-06" izz="4.816685886518848e-06" ixy="-5.129826766278253e-12" iyz="2.3470151857152982e-09" ixz="-5.261045043109544e-09"/>
  </inertial>
  <visual>
    <origin xyz="0.044123 0.194461 -0.358263" rpy="0 0 0"/>
    <geometry>
      <mesh filename="meshes/J1B_1.stl" scale="0.001 0.001 0.001"/>
    </geometry>
    <material name="silver"/>
    <material/>
  </visual>
  <collision>
    <origin xyz="0.044123 0.194461 -0.358263" rpy="0 0 0"/>
    <geometry>
      <mesh filename="meshes/J1B_1.stl" scale="0.001 0.001 0.001"/>
    </geometry>
  </collision>
</link>

<link name="J2B1">
  <inertial>
    <origin xyz="-9.654413122284211e-07 7.611213046834764e-07 0.0004999608029895852" rpy="0 0 0"/>
    <mass value="0.015413438956675116"/>
    <inertia ixx="2.4096457891887094e-06" iyy="2.4096365787320932e-06" izz="4.816685886521342e-06" ixy="-5.129827931795589e-12" iyz="2.347015185661088e-09" ixz="-5.26104504362454e-09"/>
  </inertial>
  <visual>
    <origin xyz="0.191266 -0.06151 -0.357692" rpy="0 0 0"/>
    <geometry>
      <mesh filename="meshes/J2B1.stl" scale="0.001 0.001 0.001"/>
    </geometry>
    <material name="silver"/>
    <material/>
  </visual>
  <collision>
    <origin xyz="0.191266 -0.06151 -0.357692" rpy="0 0 0"/>
    <geometry>
      <mesh filename="meshes/J2B1.stl" scale="0.001 0.001 0.001"/>
    </geometry>
  </collision>
</link>

<link name="J3B1">
  <inertial>
    <origin xyz="-1.5195966931447202e-06 8.117786757522172e-07 0.0005004567878215127" rpy="0 0 0"/>
    <mass value="0.015413438956675117"/>
    <inertia ixx="2.409645789179602e-06" iyy="2.4096365787238533e-06" izz="4.816685886521125e-06" ixy="-5.129828582316892e-12" iyz="2.3470151854984578e-09" ixz="-5.2610450426487584e-09"/>
  </inertial>
  <visual>
    <origin xyz="0.148627 -0.135042 -0.357713" rpy="0 0 0"/>
    <geometry>
      <mesh filename="meshes/J3B1.stl" scale="0.001 0.001 0.001"/>
    </geometry>
    <material name="silver"/>
    <material/>
  </visual>
  <collision>
    <origin xyz="0.148627 -0.135042 -0.357713" rpy="0 0 0"/>
    <geometry>
      <mesh filename="meshes/J3B1.stl" scale="0.001 0.001 0.001"/>
    </geometry>
  </collision>
</link>

<link name="J4B1">
  <inertial>
    <origin xyz="-8.408683301319719e-07 4.401553543309511e-07 0.000500317502139136" rpy="0 0 0"/>
    <mass value="0.015413438956675112"/>
    <inertia ixx="2.4096457891761326e-06" iyy="2.409636578739032e-06" izz="4.816685886520908e-06" ixy="-5.12982787758548e-12" iyz="2.347015185606878e-09" ixz="-5.2610450431908595e-09"/>
  </inertial>
  <visual>
    <origin xyz="-0.146621 -0.134487 -0.358359" rpy="0 0 0"/>
    <geometry>
      <mesh filename="meshes/J4B1.stl" scale="0.001 0.001 0.001"/>
    </geometry>
    <material name="silver"/>
    <material/>
  </visual>
  <collision>
    <origin xyz="-0.146621 -0.134487 -0.358359" rpy="0 0 0"/>
    <geometry>
      <mesh filename="meshes/J4B1.stl" scale="0.001 0.001 0.001"/>
    </geometry>
  </collision>
</link>

<link name="J5B1">
  <inertial>
    <origin xyz="-6.404591855746489e-07 5.026130526983308e-07 0.0004997594611538259" rpy="0 0 0"/>
    <mass value="0.015413438956675116"/>
    <inertia ixx="2.4096457891869746e-06" iyy="2.4096365787273227e-06" izz="4.816685886523185e-06" ixy="-5.129827796270317e-12" iyz="2.3470151857695083e-09" ixz="-5.2610450434077e-09"/>
  </inertial>
  <visual>
    <origin xyz="-0.188982 -0.060795 -0.358524" rpy="0 0 0"/>
    <geometry>
      <mesh filename="meshes/J5B1.stl" scale="0.001 0.001 0.001"/>
    </geometry>
    <material name="silver"/>
    <material/>
  </visual>
  <collision>
    <origin xyz="-0.188982 -0.060795 -0.358524" rpy="0 0 0"/>
    <geometry>
      <mesh filename="meshes/J5B1.stl" scale="0.001 0.001 0.001"/>
    </geometry>
  </collision>
</link>

<link name="J6B1">
  <inertial>
    <origin xyz="-1.4897596720200856e-06 8.419882958632385e-07 0.0005000925490054042" rpy="0 0 0"/>
    <mass value="0.015413438956675112"/>
    <inertia ixx="2.4096457891652906e-06" iyy="2.4096365787169144e-06" izz="4.816685886519932e-06" ixy="-5.1298284467916205e-12" iyz="2.3470151857152982e-09" ixz="-5.261045043380595e-09"/>
  </inertial>
  <visual>
    <origin xyz="-0.040877 0.194621 -0.358449" rpy="0 0 0"/>
    <geometry>
      <mesh filename="meshes/J6B1.stl" scale="0.001 0.001 0.001"/>
    </geometry>
    <material name="silver"/>
    <material/>
  </visual>
  <collision>
    <origin xyz="-0.040877 0.194621 -0.358449" rpy="0 0 0"/>
    <geometry>
      <mesh filename="meshes/J6B1.stl" scale="0.001 0.001 0.001"/>
    </geometry>
  </collision>
</link>

<link name="J6T1">
  <inertial>
    <origin xyz="-6.754336243225412e-07 8.170436158749794e-07 0.000500089685049554" rpy="0 0 0"/>
    <mass value="0.015413438956675112"/>
    <inertia ixx="2.409645789178301e-06" iyy="2.4096365787385984e-06" izz="4.816685886515162e-06" ixy="-5.129827552324828e-12" iyz="2.347015186148979e-09" ixz="-5.26104504335349e-09"/>
  </inertial>
  <visual>
    <origin xyz="-0.040874 0.19462 -0.359449" rpy="0 0 0"/>
    <geometry>
      <mesh filename="meshes/J6T1.stl" scale="0.001 0.001 0.001"/>
    </geometry>
    <material name="silver"/>
    <material/>
  </visual>
  <collision>
    <origin xyz="-0.040874 0.19462 -0.359449" rpy="0 0 0"/>
    <geometry>
      <mesh filename="meshes/J6T1.stl" scale="0.001 0.001 0.001"/>
    </geometry>
  </collision>
</link>

<link name="TOP1">
  <inertial>
    <origin xyz="-0.04215544807515086 0.19509010253129316 0.010273252577432168" rpy="0 0 0"/>
    <mass value="13.182708498536908"/>
    <inertia ixx="0.20626590341010287" iyy="0.20626511936001268" izz="0.41116715691563926" ixy="-4.366805195593659e-07" iyz="0.00019979158393172063" ixz="-0.0004478507546690899"/>
  </inertial>
  <visual>
    <origin xyz="-0.040872 0.194619 -0.360449" rpy="0 0 0"/>
    <geometry>
      <mesh filename="meshes/TOP1.stl" scale="0.001 0.001 0.001"/>
    </geometry>
    <material name="silver"/>
    <material/>
  </visual>
  <collision>
    <origin xyz="-0.040872 0.194619 -0.360449" rpy="0 0 0"/>
    <geometry>
      <mesh filename="meshes/TOP1.stl" scale="0.001 0.001 0.001"/>
    </geometry>
  </collision>
</link>

<link name="J1T1">
  <inertial>
    <origin xyz="6.783126116072236e-07 -2.9607145402010815e-07 -0.0004998482587970088" rpy="0 0 0"/>
    <mass value="0.015413438956675112"/>
    <inertia ixx="2.4096457891761326e-06" iyy="2.409636578731226e-06" izz="4.816685886517222e-06" ixy="-5.1298267120681446e-12" iyz="2.3470151859321386e-09" ixz="-5.26104504329928e-09"/>
  </inertial>
  <visual>
    <origin xyz="0.044127 0.194459 -0.360263" rpy="0 0 0"/>
    <geometry>
      <mesh filename="meshes/J1T1.stl" scale="0.001 0.001 0.001"/>
    </geometry>
    <material name="silver"/>
    <material/>
  </visual>
  <collision>
    <origin xyz="0.044127 0.194459 -0.360263" rpy="0 0 0"/>
    <geometry>
      <mesh filename="meshes/J1T1.stl" scale="0.001 0.001 0.001"/>
    </geometry>
  </collision>
</link>

<link name="J2T1">
  <inertial>
    <origin xyz="8.488847356713514e-07 -2.6382337536129397e-07 -0.0005000420609661549" rpy="0 0 0"/>
    <mass value="0.015413438956675116"/>
    <inertia ixx="2.409645789180903e-06" iyy="2.409636578732527e-06" izz="4.816685886523293e-06" ixy="-5.129827064433851e-12" iyz="2.3470151857695083e-09" ixz="-5.261045042757179e-09"/>
  </inertial>
  <visual>
    <origin xyz="0.19127 -0.061512 -0.359692" rpy="0 0 0"/>
    <geometry>
      <mesh filename="meshes/J2T1.stl" scale="0.001 0.001 0.001"/>
    </geometry>
    <material name="silver"/>
    <material/>
  </visual>
  <collision>
    <origin xyz="0.19127 -0.061512 -0.359692" rpy="0 0 0"/>
    <geometry>
      <mesh filename="meshes/J2T1.stl" scale="0.001 0.001 0.001"/>
    </geometry>
  </collision>
</link>

<link name="J3T_1">
  <inertial>
    <origin xyz="1.294729354450741e-06 -2.1316600420928644e-07 -0.0004995460761342829" rpy="0 0 0"/>
    <mass value="0.015413438956675117"/>
    <inertia ixx="2.4096457891778673e-06" iyy="2.409636578729925e-06" izz="4.816685886520908e-06" ixy="-5.129826576542873e-12" iyz="2.3470151859321386e-09" ixz="-5.261045042974019e-09"/>
  </inertial>
  <visual>
    <origin xyz="0.148632 -0.135044 -0.359713" rpy="0 0 0"/>
    <geometry>
      <mesh filename="meshes/J3T_1.stl" scale="0.001 0.001 0.001"/>
    </geometry>
    <material name="silver"/>
    <material/>
  </visual>
  <collision>
    <origin xyz="0.148632 -0.135044 -0.359713" rpy="0 0 0"/>
    <geometry>
      <mesh filename="meshes/J3T_1.stl" scale="0.001 0.001 0.001"/>
    </geometry>
  </collision>
</link>

<link name="J4T1">
  <inertial>
    <origin xyz="9.734577176290227e-07 -5.847893257138193e-07 -0.0004996853618169372" rpy="0 0 0"/>
    <mass value="0.015413438956675112"/>
    <inertia ixx="2.409645789181337e-06" iyy="2.40963657872819e-06" izz="4.816685886521992e-06" ixy="-5.129826847593416e-12" iyz="2.347015186148979e-09" ixz="-5.26104504351612e-09"/>
  </inertial>
  <visual>
    <origin xyz="-0.146617 -0.134489 -0.360359" rpy="0 0 0"/>
    <geometry>
      <mesh filename="meshes/J4T1.stl" scale="0.001 0.001 0.001"/>
    </geometry>
    <material name="silver"/>
    <material/>
  </visual>
  <collision>
    <origin xyz="-0.146617 -0.134489 -0.360359" rpy="0 0 0"/>
    <geometry>
      <mesh filename="meshes/J4T1.stl" scale="0.001 0.001 0.001"/>
    </geometry>
  </collision>
</link>

<link name="J5T_1">
  <inertial>
    <origin xyz="1.173866862436146e-06 -5.223316273325618e-07 -0.0005002434028019698" rpy="0 0 0"/>
    <mass value="0.015413438956675116"/>
    <inertia ixx="2.409645789182204e-06" iyy="2.4096365787346953e-06" izz="4.816685886523619e-06" ixy="-5.129826549437819e-12" iyz="2.3470151857695083e-09" ixz="-5.2610450431908595e-09"/>
  </inertial>
  <visual>
    <origin xyz="-0.188978 -0.060797 -0.360524" rpy="0 0 0"/>
    <geometry>
      <mesh filename="meshes/J5T_1.stl" scale="0.001 0.001 0.001"/>
    </geometry>
    <material name="silver"/>
    <material/>
  </visual>
  <collision>
    <origin xyz="-0.188978 -0.060797 -0.360524" rpy="0 0 0"/>
    <geometry>
      <mesh filename="meshes/J5T_1.stl" scale="0.001 0.001 0.001"/>
    </geometry>
  </collision>
</link>

<link name="indicator1">
  <inertial>
    <origin xyz="4.423873450270588e-06 -2.115926591825419e-06 -0.002026912016654281" rpy="0 0 0"/>
    <mass value="0.00455273252922687"/>
    <inertia ixx="1.596123294817257e-07" iyy="1.4974703211429689e-07" izz="2.936498611340208e-07" ixy="-1.8862631785502032e-11" iyz="1.4027315079376597e-10" ixz="-2.929464868599837e-10"/>
  </inertial>
  <visual>
    <origin xyz="0.001256 -0.000459 -0.358167" rpy="0 0 0"/>
    <geometry>
      <mesh filename="meshes/indicator1.stl" scale="0.001 0.001 0.001"/>
    </geometry>
    <material name="silver"/>
    <material/>
  </visual>
  <collision>
    <origin xyz="0.001256 -0.000459 -0.358167" rpy="0 0 0"/>
    <geometry>
      <mesh filename="meshes/indicator1.stl" scale="0.001 0.001 0.001"/>
    </geometry>
  </collision>
</link>

<joint name="Revolute_1" type="revolute">
  <origin xyz="-0.160375 -0.15639 0.064756" rpy="0 0 0"/>
  <parent link="base_link"/>
  <child link="X1bottom1"/>
  <axis xyz="-0.5 -0.866025 -0.0"/>
  <limit upper="0.785398" lower="-0.785398" effort="100" velocity="100"/>
</joint>
<transmission name="Revolute_1_tran">
  <type>transmission_interface/SimpleTransmission</type>
  <joint name="Revolute_1">
    <hardwareInterface>PositionJointInterface</hardwareInterface>
  </joint>
  <actuator name="Revolute_1_actr">
    <hardwareInterface>PositionJointInterface</hardwareInterface>
    <mechanicalReduction>1</mechanicalReduction>
  </actuator>
</transmission>

<joint name="Revolute_2" type="revolute">
  <origin xyz="0.173125 -0.134306 0.064756" rpy="0 0 0"/>
  <parent link="base_link"/>
  <child link="X6bottom1"/>
  <axis xyz="1.0 -0.0 0.0"/>
  <limit upper="0.785398" lower="-0.785398" effort="100" velocity="100"/>
</joint>
<transmission name="Revolute_2_tran">
  <type>transmission_interface/SimpleTransmission</type>
  <joint name="Revolute_2">
    <hardwareInterface>PositionJointInterface</hardwareInterface>
  </joint>
  <actuator name="Revolute_2_actr">
    <hardwareInterface>PositionJointInterface</hardwareInterface>
    <mechanicalReduction>1</mechanicalReduction>
  </actuator>
</transmission>

<joint name="Revolute_3" type="revolute">
  <origin xyz="0.215625 -0.060694 0.064756" rpy="0 0 0"/>
  <parent link="base_link"/>
  <child link="X5bottom1"/>
  <axis xyz="1.0 -0.0 -0.0"/>
  <limit upper="0.785398" lower="-0.785398" effort="100" velocity="100"/>
</joint>
<transmission name="Revolute_3_tran">
  <type>transmission_interface/SimpleTransmission</type>
  <joint name="Revolute_3">
    <hardwareInterface>PositionJointInterface</hardwareInterface>
  </joint>
  <actuator name="Revolute_3_actr">
    <hardwareInterface>PositionJointInterface</hardwareInterface>
    <mechanicalReduction>1</mechanicalReduction>
  </actuator>
</transmission>

<joint name="Revolute_4" type="revolute">
  <origin xyz="-0.202875 -0.082778 0.064756" rpy="0 0 0"/>
  <parent link="base_link"/>
  <child link="X2bottom1"/>
  <axis xyz="-0.5 -0.866025 0.0"/>
  <limit upper="0.785398" lower="-0.785398" effort="100" velocity="100"/>
</joint>
<transmission name="Revolute_4_tran">
  <type>transmission_interface/SimpleTransmission</type>
  <joint name="Revolute_4">
    <hardwareInterface>PositionJointInterface</hardwareInterface>
  </joint>
  <actuator name="Revolute_4_actr">
    <hardwareInterface>PositionJointInterface</hardwareInterface>
    <mechanicalReduction>1</mechanicalReduction>
  </actuator>
</transmission>

<joint name="Revolute_5" type="revolute">
  <origin xyz="0.05525 0.172916 0.064756" rpy="0 0 0"/>
  <parent link="base_link"/>
  <child link="X4bottom1"/>
  <axis xyz="0.5 -0.866025 -0.0"/>
  <limit upper="0.785398" lower="-0.785398" effort="100" velocity="100"/>
</joint>
<transmission name="Revolute_5_tran">
  <type>transmission_interface/SimpleTransmission</type>
  <joint name="Revolute_5">
    <hardwareInterface>PositionJointInterface</hardwareInterface>
  </joint>
  <actuator name="Revolute_5_actr">
    <hardwareInterface>PositionJointInterface</hardwareInterface>
    <mechanicalReduction>1</mechanicalReduction>
  </actuator>
</transmission>

<joint name="Revolute_6" type="revolute">
  <origin xyz="-0.02975 0.172916 0.064756" rpy="0 0 0"/>
  <parent link="base_link"/>
  <child link="X3bottom1"/>
  <axis xyz="0.5 -0.866025 0.0"/>
  <limit upper="0.785398" lower="-0.785398" effort="100" velocity="100"/>
</joint>
<transmission name="Revolute_6_tran">
  <type>transmission_interface/SimpleTransmission</type>
  <joint name="Revolute_6">
    <hardwareInterface>PositionJointInterface</hardwareInterface>
  </joint>
  <actuator name="Revolute_6_actr">
    <hardwareInterface>PositionJointInterface</hardwareInterface>
    <mechanicalReduction>1</mechanicalReduction>
  </actuator>
</transmission>

<joint name="Revolute_7" type="revolute">
  <origin xyz="-0.0255 0.025047 0.005976" rpy="0 0 0"/>
  <parent link="X6bottom1"/>
  <child link="cylinder61"/>
  <axis xyz="0.0 0.972693 0.232097"/>
  <limit upper="0.785398" lower="-0.785398" effort="100" velocity="100"/>
</joint>
<transmission name="Revolute_7_tran">
  <type>transmission_interface/SimpleTransmission</type>
  <joint name="Revolute_7">
    <hardwareInterface>PositionJointInterface</hardwareInterface>
  </joint>
  <actuator name="Revolute_7_actr">
    <hardwareInterface>PositionJointInterface</hardwareInterface>
    <mechanicalReduction>1</mechanicalReduction>
  </actuator>
</transmission>

<joint name="Revolute_8" type="revolute">
  <origin xyz="-0.0255 -0.023231 0.011107" rpy="0 0 0"/>
  <parent link="X5bottom1"/>
  <child link="cylinder51"/>
  <axis xyz="-0.0 -0.902181 0.431357"/>
  <limit upper="0.785398" lower="-0.785398" effort="100" velocity="100"/>
</joint>
<transmission name="Revolute_8_tran">
  <type>transmission_interface/SimpleTransmission</type>
  <joint name="Revolute_8">
    <hardwareInterface>PositionJointInterface</hardwareInterface>
  </joint>
  <actuator name="Revolute_8_actr">
    <hardwareInterface>PositionJointInterface</hardwareInterface>
    <mechanicalReduction>1</mechanicalReduction>
  </actuator>
</transmission>

<joint name="Revolute_9" type="revolute">
  <origin xyz="0.032916 0.010441 -0.010994" rpy="0 0 0"/>
  <parent link="X1bottom1"/>
  <child link="cylinder11"/>
  <axis xyz="0.783126 -0.452138 -0.426948"/>
  <limit upper="0.785398" lower="-0.785398" effort="100" velocity="100"/>
</joint>
<transmission name="Revolute_9_tran">
  <type>transmission_interface/SimpleTransmission</type>
  <joint name="Revolute_9">
    <hardwareInterface>PositionJointInterface</hardwareInterface>
  </joint>
  <actuator name="Revolute_9_actr">
    <hardwareInterface>PositionJointInterface</hardwareInterface>
    <mechanicalReduction>1</mechanicalReduction>
  </actuator>
</transmission>

<joint name="Revolute_10" type="revolute">
  <origin xyz="0.03441 0.009579 0.006124" rpy="0 0 0"/>
  <parent link="X2bottom1"/>
  <child link="cylinder21"/>
  <axis xyz="0.841174 -0.485652 0.23784"/>
  <limit upper="0.785398" lower="-0.785398" effort="100" velocity="100"/>
</joint>
<transmission name="Revolute_10_tran">
  <type>transmission_interface/SimpleTransmission</type>
  <joint name="Revolute_10">
    <hardwareInterface>PositionJointInterface</hardwareInterface>
  </joint>
  <actuator name="Revolute_10_actr">
    <hardwareInterface>PositionJointInterface</hardwareInterface>
    <mechanicalReduction>1</mechanicalReduction>
  </actuator>
</transmission>

<joint name="Revolute_11" type="revolute">
  <origin xyz="0.007345 0.033686 0.011164" rpy="0 0 0"/>
  <parent link="X3bottom1"/>
  <child link="cylinder31"/>
  <axis xyz="0.780387 0.450557 0.433584"/>
  <limit upper="0.785398" lower="-0.785398" effort="100" velocity="100"/>
</joint>
<transmission name="Revolute_11_tran">
  <type>transmission_interface/SimpleTransmission</type>
  <joint name="Revolute_11">
    <hardwareInterface>PositionJointInterface</hardwareInterface>
  </joint>
  <actuator name="Revolute_11_actr">
    <hardwareInterface>PositionJointInterface</hardwareInterface>
    <mechanicalReduction>1</mechanicalReduction>
  </actuator>
</transmission>

<joint name="Revolute_12" type="revolute">
  <origin xyz="0.008953 0.034614 -0.005921" rpy="0 0 0"/>
  <parent link="X4bottom1"/>
  <child link="cylinder41"/>
  <axis xyz="0.842824 0.486605 -0.229918"/>
  <limit upper="0.785398" lower="-0.785398" effort="100" velocity="100"/>
</joint>
<transmission name="Revolute_12_tran">
  <type>transmission_interface/SimpleTransmission</type>
  <joint name="Revolute_12">
    <hardwareInterface>PositionJointInterface</hardwareInterface>
  </joint>
  <actuator name="Revolute_12_actr">
    <hardwareInterface>PositionJointInterface</hardwareInterface>
    <mechanicalReduction>1</mechanicalReduction>
  </actuator>
</transmission>

<joint name="Slider_13" type="prismatic">
  <origin xyz="0.068432 -0.03984 0.228025" rpy="0 0 0"/>
  <parent link="cylinder11"/>
  <child link="rod11"/>
  <axis xyz="0.369151 -0.214507 0.904276"/>
  <limit upper="0.19" lower="0.0" effort="100" velocity="100"/>
</joint>
<transmission name="Slider_13_tran">
  <type>transmission_interface/SimpleTransmission</type>
  <joint name="Slider_13">
    <hardwareInterface>PositionJointInterface</hardwareInterface>
  </joint>
  <actuator name="Slider_13_actr">
    <hardwareInterface>PositionJointInterface</hardwareInterface>
    <mechanicalReduction>1</mechanicalReduction>
  </actuator>
</transmission>

<joint name="Slider_14" type="prismatic">
  <origin xyz="-0.02256 0.116805 0.210031" rpy="0 0 0"/>
  <parent link="cylinder21"/>
  <child link="rod21"/>
  <axis xyz="-0.00375 0.434573 0.900629"/>
  <limit upper="0.19" lower="0.0" effort="100" velocity="100"/>
</joint>
<transmission name="Slider_14_tran">
  <type>transmission_interface/SimpleTransmission</type>
  <joint name="Slider_14">
    <hardwareInterface>PositionJointInterface</hardwareInterface>
  </joint>
  <actuator name="Slider_14_actr">
    <hardwareInterface>PositionJointInterface</hardwareInterface>
    <mechanicalReduction>1</mechanicalReduction>
  </actuator>
</transmission>

<joint name="Slider_15" type="prismatic">
  <origin xyz="-0.110669 -0.062847 0.205106" rpy="0 0 0"/>
  <parent link="cylinder31"/>
  <child link="rod31"/>
  <axis xyz="-0.377381 -0.213518 0.901107"/>
  <limit upper="0.19" lower="0.0" effort="100" velocity="100"/>
</joint>
<transmission name="Slider_15_tran">
  <type>transmission_interface/SimpleTransmission</type>
  <joint name="Slider_15">
    <hardwareInterface>PositionJointInterface</hardwareInterface>
  </joint>
  <actuator name="Slider_15_actr">
    <hardwareInterface>PositionJointInterface</hardwareInterface>
    <mechanicalReduction>1</mechanicalReduction>
  </actuator>
</transmission>

<joint name="Slider_16" type="prismatic">
  <origin xyz="0.0673 -0.064247 0.22273" rpy="0 0 0"/>
  <parent link="cylinder41"/>
  <child link="rod41"/>
  <axis xyz="0.370839 -0.215482 0.903353"/>
  <limit upper="0.19" lower="0.0" effort="100" velocity="100"/>
</joint>
<transmission name="Slider_16_tran">
  <type>transmission_interface/SimpleTransmission</type>
  <joint name="Slider_16">
    <hardwareInterface>PositionJointInterface</hardwareInterface>
  </joint>
  <actuator name="Slider_16_actr">
    <hardwareInterface>PositionJointInterface</hardwareInterface>
    <mechanicalReduction>1</mechanicalReduction>
  </actuator>
</transmission>

<joint name="Slider_17" type="prismatic">
  <origin xyz="-0.0009 0.126758 0.20542" rpy="0 0 0"/>
  <parent link="cylinder51"/>
  <child link="rod51"/>
  <axis xyz="-0.003749 0.431354 0.902175"/>
  <limit upper="0.19" lower="0.0" effort="100" velocity="100"/>
</joint>
<transmission name="Slider_17_tran">
  <type>transmission_interface/SimpleTransmission</type>
  <joint name="Slider_17">
    <hardwareInterface>PositionJointInterface</hardwareInterface>
  </joint>
  <actuator name="Slider_17_actr">
    <hardwareInterface>PositionJointInterface</hardwareInterface>
    <mechanicalReduction>1</mechanicalReduction>
  </actuator>
</transmission>

<joint name="Slider_18" type="prismatic">
  <origin xyz="-0.091079 -0.076585 0.210013" rpy="0 0 0"/>
  <parent link="cylinder61"/>
  <child link="rod61"/>
  <axis xyz="-0.379485 -0.214736 0.899933"/>
  <limit upper="0.19" lower="0.0" effort="100" velocity="100"/>
</joint>
<transmission name="Slider_18_tran">
  <type>transmission_interface/SimpleTransmission</type>
  <joint name="Slider_18">
    <hardwareInterface>PositionJointInterface</hardwareInterface>
  </joint>
  <actuator name="Slider_18_actr">
    <hardwareInterface>PositionJointInterface</hardwareInterface>
    <mechanicalReduction>1</mechanicalReduction>
  </actuator>
</transmission>

<joint name="Revolute_19" type="revolute">
  <origin xyz="0.000223 -0.000129 0.000545" rpy="0 0 0"/>
  <parent link="rod11"/>
  <child link="piston11"/>
  <axis xyz="0.369151 -0.214507 0.904276"/>
  <limit upper="6.283185" lower="0.0" effort="100" velocity="100"/>
</joint>
<transmission name="Revolute_19_tran">
  <type>transmission_interface/SimpleTransmission</type>
  <joint name="Revolute_19">
    <hardwareInterface>PositionJointInterface</hardwareInterface>
  </joint>
  <actuator name="Revolute_19_actr">
    <hardwareInterface>PositionJointInterface</hardwareInterface>
    <mechanicalReduction>1</mechanicalReduction>
  </actuator>
</transmission>

<joint name="Revolute_20" type="revolute">
  <origin xyz="-4e-06 0.00048 0.000995" rpy="0 0 0"/>
  <parent link="rod21"/>
  <child link="piston21"/>
  <axis xyz="-0.00375 0.434573 0.900629"/>
  <limit upper="6.283185" lower="0.0" effort="100" velocity="100"/>
</joint>
<transmission name="Revolute_20_tran">
  <type>transmission_interface/SimpleTransmission</type>
  <joint name="Revolute_20">
    <hardwareInterface>PositionJointInterface</hardwareInterface>
  </joint>
  <actuator name="Revolute_20_actr">
    <hardwareInterface>PositionJointInterface</hardwareInterface>
    <mechanicalReduction>1</mechanicalReduction>
  </actuator>
</transmission>

<joint name="Revolute_21" type="revolute">
  <origin xyz="-0.000369 -0.00021 0.000883" rpy="0 0 0"/>
  <parent link="rod31"/>
  <child link="piston31"/>
  <axis xyz="-0.377381 -0.213518 0.901107"/>
  <limit upper="6.283185" lower="0.0" effort="100" velocity="100"/>
</joint>
<transmission name="Revolute_21_tran">
  <type>transmission_interface/SimpleTransmission</type>
  <joint name="Revolute_21">
    <hardwareInterface>PositionJointInterface</hardwareInterface>
  </joint>
  <actuator name="Revolute_21_actr">
    <hardwareInterface>PositionJointInterface</hardwareInterface>
    <mechanicalReduction>1</mechanicalReduction>
  </actuator>
</transmission>

<joint name="Revolute_22" type="revolute">
  <origin xyz="-0.000399 -0.000226 0.000946" rpy="0 0 0"/>
  <parent link="rod61"/>
  <child link="piston61"/>
  <axis xyz="-0.379485 -0.214736 0.899933"/>
  <limit upper="6.283185" lower="0.0" effort="100" velocity="100"/>
</joint>
<transmission name="Revolute_22_tran">
  <type>transmission_interface/SimpleTransmission</type>
  <joint name="Revolute_22">
    <hardwareInterface>PositionJointInterface</hardwareInterface>
  </joint>
  <actuator name="Revolute_22_actr">
    <hardwareInterface>PositionJointInterface</hardwareInterface>
    <mechanicalReduction>1</mechanicalReduction>
  </actuator>
</transmission>

<joint name="Revolute_23" type="revolute">
  <origin xyz="-6e-06 0.000667 0.001393" rpy="0 0 0"/>
  <parent link="rod51"/>
  <child link="piston51"/>
  <axis xyz="-0.003749 0.431354 0.902175"/>
  <limit upper="6.283185" lower="0.0" effort="100" velocity="100"/>
</joint>
<transmission name="Revolute_23_tran">
  <type>transmission_interface/SimpleTransmission</type>
  <joint name="Revolute_23">
    <hardwareInterface>PositionJointInterface</hardwareInterface>
  </joint>
  <actuator name="Revolute_23_actr">
    <hardwareInterface>PositionJointInterface</hardwareInterface>
    <mechanicalReduction>1</mechanicalReduction>
  </actuator>
</transmission>

<joint name="Revolute_24" type="revolute">
  <origin xyz="0.00037 -0.000214 0.0009" rpy="0 0 0"/>
  <parent link="rod41"/>
  <child link="piston41"/>
  <axis xyz="0.370839 -0.215482 0.903353"/>
  <limit upper="6.283185" lower="0.0" effort="100" velocity="100"/>
</joint>
<transmission name="Revolute_24_tran">
  <type>transmission_interface/SimpleTransmission</type>
  <joint name="Revolute_24">
    <hardwareInterface>PositionJointInterface</hardwareInterface>
  </joint>
  <actuator name="Revolute_24_actr">
    <hardwareInterface>PositionJointInterface</hardwareInterface>
    <mechanicalReduction>1</mechanicalReduction>
  </actuator>
</transmission>

<joint name="Revolute_25" type="revolute">
  <origin xyz="0.004703 0.002865 0.047121" rpy="0 0 0"/>
  <parent link="piston61"/>
  <child link="X6top1"/>
  <axis xyz="-0.779795 -0.449231 -0.436018"/>
  <limit upper="0.785398" lower="-0.785398" effort="100" velocity="100"/>
</joint>
<transmission name="Revolute_25_tran">
  <type>transmission_interface/SimpleTransmission</type>
  <joint name="Revolute_25">
    <hardwareInterface>PositionJointInterface</hardwareInterface>
  </joint>
  <actuator name="Revolute_25_actr">
    <hardwareInterface>PositionJointInterface</hardwareInterface>
    <mechanicalReduction>1</mechanicalReduction>
  </actuator>
</transmission>

<joint name="Revolute_26" type="revolute">
  <origin xyz="0.036291 0.003778 0.030321" rpy="0 0 0"/>
  <parent link="piston11"/>
  <child link="X1top1"/>
  <axis xyz="-0.844029 -0.484671 0.229586"/>
  <limit upper="0.785398" lower="-0.785398" effort="100" velocity="100"/>
</joint>
<transmission name="Revolute_26_tran">
  <type>transmission_interface/SimpleTransmission</type>
  <joint name="Revolute_26">
    <hardwareInterface>PositionJointInterface</hardwareInterface>
  </joint>
  <actuator name="Revolute_26_actr">
    <hardwareInterface>PositionJointInterface</hardwareInterface>
    <mechanicalReduction>1</mechanicalReduction>
  </actuator>
</transmission>

<joint name="Revolute_27" type="revolute">
  <origin xyz="0.034764 -0.020174 0.025202" rpy="0 0 0"/>
  <parent link="piston41"/>
  <child link="X4top1"/>
  <axis xyz="-0.78153 0.453054 0.428898"/>
  <limit upper="0.785398" lower="-0.785398" effort="100" velocity="100"/>
</joint>
<transmission name="Revolute_27_tran">
  <type>transmission_interface/SimpleTransmission</type>
  <joint name="Revolute_27">
    <hardwareInterface>PositionJointInterface</hardwareInterface>
  </joint>
  <actuator name="Revolute_27_actr">
    <hardwareInterface>PositionJointInterface</hardwareInterface>
    <mechanicalReduction>1</mechanicalReduction>
  </actuator>
</transmission>

<joint name="Revolute_28" type="revolute">
  <origin xyz="0.021283 0.004826 0.042124" rpy="0 0 0"/>
  <parent link="piston51"/>
  <child link="X5top1"/>
  <axis xyz="-0.840501 0.487444 -0.236553"/>
  <limit upper="0.785398" lower="-0.785398" effort="100" velocity="100"/>
</joint>
<transmission name="Revolute_28_tran">
  <type>transmission_interface/SimpleTransmission</type>
  <joint name="Revolute_28">
    <hardwareInterface>PositionJointInterface</hardwareInterface>
  </joint>
  <actuator name="Revolute_28_actr">
    <hardwareInterface>PositionJointInterface</hardwareInterface>
    <mechanicalReduction>1</mechanicalReduction>
  </actuator>
</transmission>

<joint name="Revolute_29" type="revolute">
  <origin xyz="-0.00869 -0.034684 0.005904" rpy="0 0 0"/>
  <parent link="X1top1"/>
  <child link="UJ11"/>
  <axis xyz="0.498367 -0.866964 0.001935"/>
  <limit upper="6.283185" lower="0.0" effort="100" velocity="100"/>
</joint>
<transmission name="Revolute_29_tran">
  <type>transmission_interface/SimpleTransmission</type>
  <joint name="Revolute_29">
    <hardwareInterface>PositionJointInterface</hardwareInterface>
  </joint>
  <actuator name="Revolute_29_actr">
    <hardwareInterface>PositionJointInterface</hardwareInterface>
    <mechanicalReduction>1</mechanicalReduction>
  </actuator>
</transmission>

<joint name="Revolute_30" type="revolute">
  <origin xyz="-0.007051 -0.03378 -0.011069" rpy="0 0 0"/>
  <parent link="X6top1"/>
  <child link="UJ61"/>
  <axis xyz="0.498367 -0.866964 0.001935"/>
  <limit upper="6.283185" lower="0.0" effort="100" velocity="100"/>
</joint>
<transmission name="Revolute_30_tran">
  <type>transmission_interface/SimpleTransmission</type>
  <joint name="Revolute_30">
    <hardwareInterface>PositionJointInterface</hardwareInterface>
  </joint>
  <actuator name="Revolute_30_actr">
    <hardwareInterface>PositionJointInterface</hardwareInterface>
    <mechanicalReduction>1</mechanicalReduction>
  </actuator>
</transmission>

<joint name="Revolute_31" type="revolute">
  <origin xyz="-0.008516 0.034706 -0.006025" rpy="0 0 0"/>
  <parent link="X5top1"/>
  <child link="UJ51"/>
  <axis xyz="0.501629 0.865083 0.000253"/>
  <limit upper="6.283185" lower="0.0" effort="100" velocity="100"/>
</joint>
<transmission name="Revolute_31_tran">
  <type>transmission_interface/SimpleTransmission</type>
  <joint name="Revolute_31">
    <hardwareInterface>PositionJointInterface</hardwareInterface>
  </joint>
  <actuator name="Revolute_31_actr">
    <hardwareInterface>PositionJointInterface</hardwareInterface>
    <mechanicalReduction>1</mechanicalReduction>
  </actuator>
</transmission>

<joint name="Revolute_32" type="revolute">
  <origin xyz="-0.007012 0.033829 0.010943" rpy="0 0 0"/>
  <parent link="X4top1"/>
  <child link="UJ41"/>
  <axis xyz="0.501629 0.865083 0.000253"/>
  <limit upper="6.283185" lower="0.0" effort="100" velocity="100"/>
</joint>
<transmission name="Revolute_32_tran">
  <type>transmission_interface/SimpleTransmission</type>
  <joint name="Revolute_32">
    <hardwareInterface>PositionJointInterface</hardwareInterface>
  </joint>
  <actuator name="Revolute_32_actr">
    <hardwareInterface>PositionJointInterface</hardwareInterface>
    <mechanicalReduction>1</mechanicalReduction>
  </actuator>
</transmission>

<joint name="Revolute_33" type="revolute">
  <origin xyz="-0.015064 0.016268 0.041942" rpy="0 0 0"/>
  <parent link="piston31"/>
  <child link="X3top1"/>
  <axis xyz="-0.001325 -0.972931 -0.231091"/>
  <limit upper="0.785398" lower="-0.785398" effort="100" velocity="100"/>
</joint>
<transmission name="Revolute_33_tran">
  <type>transmission_interface/SimpleTransmission</type>
  <joint name="Revolute_33">
    <hardwareInterface>PositionJointInterface</hardwareInterface>
  </joint>
  <actuator name="Revolute_33_actr">
    <hardwareInterface>PositionJointInterface</hardwareInterface>
    <mechanicalReduction>1</mechanicalReduction>
  </actuator>
</transmission>

<joint name="Revolute_34" type="continuous">
  <origin xyz="0.025716 -0.024858 -0.005837" rpy="0 0 0"/>
  <parent link="X3top1"/>
  <child link="UJ31"/>
  <axis xyz="0.999996 -0.001881 0.002188"/>
</joint>
<transmission name="Revolute_34_tran">
  <type>transmission_interface/SimpleTransmission</type>
  <joint name="Revolute_34">
    <hardwareInterface>PositionJointInterface</hardwareInterface>
  </joint>
  <actuator name="Revolute_34_actr">
    <hardwareInterface>PositionJointInterface</hardwareInterface>
    <mechanicalReduction>1</mechanicalReduction>
  </actuator>
</transmission>

<joint name="Revolute_35" type="revolute">
  <origin xyz="-8.3e-05 0.040352 0.024949" rpy="0 0 0"/>
  <parent link="piston21"/>
  <child link="X2top1"/>
  <axis xyz="-0.002645 -0.900636 0.434566"/>
  <limit upper="0.785398" lower="-0.785398" effort="100" velocity="100"/>
</joint>
<transmission name="Revolute_35_tran">
  <type>transmission_interface/SimpleTransmission</type>
  <joint name="Revolute_35">
    <hardwareInterface>PositionJointInterface</hardwareInterface>
  </joint>
  <actuator name="Revolute_35_actr">
    <hardwareInterface>PositionJointInterface</hardwareInterface>
    <mechanicalReduction>1</mechanicalReduction>
  </actuator>
</transmission>

<joint name="Revolute_36" type="revolute">
  <origin xyz="-0.025817 -0.022918 0.011025" rpy="0 0 0"/>
  <parent link="X2top1"/>
  <child link="UJ21"/>
  <axis xyz="-0.999996 0.001881 -0.002188"/>
  <limit upper="6.283185" lower="0.0" effort="100" velocity="100"/>
</joint>
<transmission name="Revolute_36_tran">
  <type>transmission_interface/SimpleTransmission</type>
  <joint name="Revolute_36">
    <hardwareInterface>PositionJointInterface</hardwareInterface>
  </joint>
  <actuator name="Revolute_36_actr">
    <hardwareInterface>PositionJointInterface</hardwareInterface>
    <mechanicalReduction>1</mechanicalReduction>
  </actuator>
</transmission>

<joint name="Rigid_59" type="fixed">
  <origin xyz="-0.01292 0.022363 0.039706" rpy="0 0 0"/>
  <parent link="UJ11"/>
  <child link="J1B_1"/>
</joint>

<joint name="Rigid_60" type="fixed">
  <origin xyz="0.025663 -1e-05 0.039812" rpy="0 0 0"/>
  <parent link="UJ21"/>
  <child link="J2B1"/>
</joint>

<joint name="Rigid_61" type="fixed">
  <origin xyz="-0.025836 8.7e-05 0.039699" rpy="0 0 0"/>
  <parent link="UJ31"/>
  <child link="J3B1"/>
</joint>

<joint name="Rigid_62" type="fixed">
  <origin xyz="-0.013004 -0.022237 0.039749" rpy="0 0 0"/>
  <parent link="UJ41"/>
  <child link="J4B1"/>
</joint>

<joint name="Rigid_63" type="fixed">
  <origin xyz="-0.013004 -0.022237 0.039749" rpy="0 0 0"/>
  <parent link="UJ51"/>
  <child link="J5B1"/>
</joint>

<joint name="Rigid_64" type="fixed">
  <origin xyz="-0.012922 0.022364 0.040706" rpy="0 0 0"/>
  <parent link="UJ61"/>
  <child link="J6B1"/>
</joint>

<joint name="Rigid_65" type="fixed">
  <origin xyz="-3e-06 1e-06 0.001" rpy="0 0 0"/>
  <parent link="J6B1"/>
  <child link="J6T1"/>
</joint>

<joint name="Rigid_66" type="fixed">
  <origin xyz="-2e-06 1e-06 0.001" rpy="0 0 0"/>
  <parent link="J6T1"/>
  <child link="TOP1"/>
</joint>

<joint name="Rigid_67" type="fixed">
  <origin xyz="-0.084999 0.00016 -0.000186" rpy="0 0 0"/>
  <parent link="TOP1"/>
  <child link="J1T1"/>
</joint>

<joint name="Rigid_68" type="fixed">
  <origin xyz="-0.232142 0.256131 -0.000757" rpy="0 0 0"/>
  <parent link="TOP1"/>
  <child link="J2T1"/>
</joint>

<joint name="Rigid_69" type="fixed">
  <origin xyz="-0.189504 0.329663 -0.000736" rpy="0 0 0"/>
  <parent link="TOP1"/>
  <child link="J3T_1"/>
</joint>

<joint name="Rigid_70" type="fixed">
  <origin xyz="0.105745 0.329108 -9e-05" rpy="0 0 0"/>
  <parent link="TOP1"/>
  <child link="J4T1"/>
</joint>

<joint name="Rigid_71" type="fixed">
  <origin xyz="0.148106 0.255416 7.5e-05" rpy="0 0 0"/>
  <parent link="TOP1"/>
  <child link="J5T_1"/>
</joint>

<joint name="Rigid_77" type="fixed">
  <origin xyz="-0.042128 0.195078 -0.002282" rpy="0 0 0"/>
  <parent link="TOP1"/>
  <child link="indicator1"/>
</joint>

</robot>
